Workbook

Sheet Income Statement
A1: Income Statement — Months 6–10 Actual (Adjusted for One-Time Items) + Months 11–13 Forecast
A2: All figures in EUR (€). Unaudited. Blue = input · black = formula · green = link to another tab · yellow = adjustment assumption · purple-shaded italic columns = FORECAST. | G2: =(F6/B6)^(1/4)-1 -> 0.031562279
H3: FORECAST (Months 11–13)
A4: Line Item | B4: Month 6 | C4: Month 7 | D4: Month 8 | E4: Month 9 | F4: Month 10 | G4: 5-Month Total | H4: Month 11 (F) | I4: Month 12 (F) | J4: Month 13 (F) | K4: 3-Mo Forecast Total
A5: Revenue | B5: 187400 | C5: 194200 | D5: 201900 | E5: 198300 | F5: 210100 | G5: =SUM(B5:F5) -> 991900 | H5: =IF(Analysis!$F$10="Yes",F5*(1+Analysis!$E$10),Analysis!$C$10) -> 216192.27 | I5: =IF(Analysis!$F$10="Yes",H5*(1+Analysis!$E$10),Analysis!$C$10) -> 222461.21 | J5: =IF(Analysis!$F$10="Yes",I5*(1+Analysis!$E$10),Analysis!$C$10) -> 228911.92 | K5: =SUM(H5:J5) -> 667565.4
A6: COGS (incl. subcontractors) — adjusted | B6: =B39-B33 -> 61200 | C6: =C39-C33 -> 64500 | D6: =D39-D33 -> 81300 | E6: =E39-E33 -> 67100 | F6: =F39-F33 -> 69300 | G6: =SUM(B6:F6) -> 343400 | H6: =IF(Analysis!$F$12="Yes",F6*(1+Analysis!$E$12),Analysis!$C$12) -> 71487.266 | I6: =IF(Analysis!$F$12="Yes",H6*(1+Analysis!$E$12),Analysis!$C$12) -> 73743.567 | J6: =IF(Analysis!$F$12="Yes",I6*(1+Analysis!$E$12),Analysis!$C$12) -> 76071.082 | K6: =SUM(H6:J6) -> 221301.92
A7: Gross Profit | B7: =B5-B6 -> 126200 | C7: =C5-C6 -> 129700 | D7: =D5-D6 -> 120600 | E7: =E5-E6 -> 131200 | F7: =F5-F6 -> 140800 | G7: =SUM(B7:F7) -> 648500 | H7: =H5-H6 -> 144705.01 | I7: =I5-I6 -> 148717.64 | J7: =J5-J6 -> 152840.83 | K7: =SUM(H7:J7) -> 446263.48
A8: Gross Margin % | B8: =IF(B5=0,0,B7/B5) -> 0.67342583 | C8: =IF(C5=0,0,C7/C5) -> 0.66786818 | D8: =IF(D5=0,0,D7/D5) -> 0.59732541 | E8: =IF(E5=0,0,E7/E5) -> 0.6616238 | F8: =IF(F5=0,0,F7/F5) -> 0.67015707 | G8: =IF(G5=0,0,G7/G5) -> 0.65379575 | H8: =IF(H5=0,0,H7/H5) -> 0.66933478 | I8: =IF(I5=0,0,I7/I5) -> 0.66851044 | ... K8: =IF(K5=0,0,K7/K5) -> 0.66849403
A10: Operating Expenses
A11: Payroll — adjusted | B11: =B40-B34 -> 72000 | C11: =C40-C34 -> 72000 | D11: =D40-D34 -> 72000 | E11: =E40-E34 -> 72000 | F11: =F40-F34 -> 72000 | G11: =SUM(B11:F11) -> 360000 | H11: =Analysis!$C$14 -> 72000 | I11: =Analysis!$C$14 -> 72000 | J11: =Analysis!$C$14 -> 72000 | K11: =SUM(H11:J11) -> 216000
A12: Consulting & Professional Fees — adjusted | B12: =B41-B35 -> 4100 | C12: =C41-C35 -> 3800 | D12: =D41-D35 -> 4200 | E12: =E41-E35 -> 4500 | F12: =F41-F35 -> 3900 | G12: =SUM(B12:F12) -> 20500 | H12: =Analysis!$C$16 -> 4100 | I12: =Analysis!$C$16 -> 4100 | J12: =Analysis!$C$16 -> 4100 | K12: =SUM(H12:J12) -> 12300
A13: Other OpEx | B13: 22300 | C13: 23100 | D13: 21900 | E13: 24600 | F13: 23800 | G13: =SUM(B13:F13) -> 115700 | H13: =Analysis!$C$18 -> 23140 | I13: =Analysis!$C$18 -> 23140 | J13: =Analysis!$C$18 -> 23140 | K13: =SUM(H13:J13) -> 69420
A14: Total Operating Expenses | B14: =SUM(B11:B13) -> 98400 | C14: =SUM(C11:C13) -> 98900 | D14: =SUM(D11:D13) -> 98100 | E14: =SUM(E11:E13) -> 101100 | F14: =SUM(F11:F13) -> 99700 | G14: =SUM(B14:F14) -> 496200 | H14: =SUM(H11:H13) -> 99240 | I14: =SUM(I11:I13) -> 99240 | J14: =SUM(J11:J13) -> 99240 | K14: =SUM(H14:J14) -> 297720
A16: Operating Income | B16: =B7-B14 -> 27800 | C16: =C7-C14 -> 30800 | D16: =D7-D14 -> 22500 | E16: =E7-E14 -> 30100 | F16: =F7-F14 -> 41100 | G16: =SUM(B16:F16) -> 152300 | H16: =H7-H14 -> 45465.008 | I16: =I7-I14 -> 49477.638 | J16: =J7-J14 -> 53600.835 | K16: =SUM(H16:J16) -> 148543.48
A17: Operating Margin % | B17: =IF(B5=0,0,B16/B5) -> 0.14834578 | C17: =IF(C5=0,0,C16/C5) -> 0.15859938 | D17: =IF(D5=0,0,D16/D5) -> 0.11144131 | E17: =IF(E5=0,0,E16/E5) -> 0.15179022 | F17: =IF(F5=0,0,F16/F5) -> 0.19562113 | G17: =IF(G5=0,0,G16/G5) -> 0.1535437 | H17: =IF(H5=0,0,H16/H5) -> 0.21029895 | I17: =IF(I5=0,0,I16/I5) -> 0.22241019 | ... K17: =IF(K5=0,0,K16/K5) -> 0.22251525
A19: Net Income (Scrubbed) | B19: =B16 -> 27800 | C19: =C16 -> 30800 | D19: =D16 -> 22500 | E19: =E16 -> 30100 | F19: =F16 -> 41100 | G19: =SUM(B19:F19) -> 152300 | H19: =H16 -> 45465.008 | I19: =I16 -> 49477.638 | J19: =J16 -> 53600.835 | K19: =SUM(H19:J19) -> 148543.48
A20: Net Margin % | B20: =IF(B5=0,0,B19/B5) -> 0.14834578 | C20: =IF(C5=0,0,C19/C5) -> 0.15859938 | D20: =IF(D5=0,0,D19/D5) -> 0.11144131 | E20: =IF(E5=0,0,E19/E5) -> 0.15179022 | F20: =IF(F5=0,0,F19/F5) -> 0.19562113 | G20: =IF(G5=0,0,G19/G5) -> 0.1535437 | H20: =IF(H5=0,0,H19/H5) -> 0.21029895 | I20: =IF(I5=0,0,I19/I5) -> 0.22241019 | ... K20: =IF(K5=0,0,K19/K5) -> 0.22251525
A22: Net Profit (as reported) | B22: 27800 | C22: 30800 | D22: -12300 | E22: -6900 | F22: 41100 | G22: =SUM(B22:F22) -> 80500
A23: Check: Adjusted NI − (Reported NP + adjustments) → must be 0 | B23: =B19-(B22+B36) -> 0 | C23: =C19-(C22+C36) -> 0 | D23: =D19-(D22+D36) -> 0 | E23: =E19-(E22+E36) -> 0 | F23: =F19-(F22+F36) -> 0 | G23: =G19-(G22+G36) -> 0
A25: Notes
A26: 1. Source: bookkeeper P&L export; figures are unaudited.
A27: 2. No interest, tax, depreciation or other non-operating items were provided, so Net Income equals Operating Income.
A28: 3. Months 6–10 are shown adjusted: one-time items in rows 33–35 are removed from the as-reported figures in rows 39–41. Row 23 reconciles back to reported net profit.
A29: 4. Month 8 COGS is still elevated after the adjustment (€81,300, ~40% of revenue vs ~33% in other months) and is worth querying.
A30: 5. Forecast: Revenue and COGS compound at their monthly growth rate where it exceeds the significance threshold (Analysis tab); OpEx is held at its adjusted 5-month average.
A32: ONE-TIME ITEMS SCRUBBED (normalization adjustments, €)
A33: Duplicated one-time contractor expense — removed from COGS | D33: 17400 | G33: =SUM(B33:F33) -> 17400
A34: Duplicated one-time contractor expense — removed from Payroll | D34: 17400 | G34: =SUM(B34:F34) -> 17400
A35: One-time consulting fee — removed from Consulting & Prof. Fees | E35: 37000 | G35: =SUM(B35:F35) -> 37000
A36: Total adjustments (added back to Net Income) | B36: =SUM(B33:B35) -> 0 | C36: =SUM(C33:C35) -> 0 | D36: =SUM(D33:D35) -> 34800 | E36: =SUM(E33:E35) -> 37000 | F36: =SUM(F33:F35) -> 0 | G36: =SUM(G33:G35) -> 71800
A38: AS-REPORTED FIGURES (bookkeeper export, before adjustments)
A39: COGS (incl. subcontractors) — as reported | B39: 61200 | C39: 64500 | D39: 98700 | E39: 67100 | F39: 69300 | G39: =SUM(B39:F39) -> 360800
A40: Payroll — as reported | B40: 72000 | C40: 72000 | D40: 89400 | E40: 72000 | F40: 72000 | G40: =SUM(B40:F40) -> 377400
A41: Consulting & Professional Fees — as reported | B41: 4100 | C41: 3800 | D41: 4200 | E41: 41500 | F41: 3900 | G41: =SUM(B41:F41) -> 57500

Sheet Analysis
A1: Analysis — Adjusted Months 6–10 (averages, growth, % of revenue)
A2: Built on the adjusted (one-time items scrubbed) figures on the Income Statement. Growth = compound monthly growth from Month 6 to Month 10. Green = link to Income Statement; blue/yellow = assumption.
A4: ASSUMPTIONS
A5: Growth periods (Month 6 → Month 10) | C5: 4
A6: Significance threshold for applying a growth rate (absolute, monthly) | C6: 0.02
C8: MONTHLY | G8: ANNUALIZED
A9: Line Item | B9: Basis | C9: 5-Month Avg | D9: Trailing 3-Mo Avg (M8–M10) | E9: Monthly Growth Rate | F9: Significant? | G9: 5-Month Avg × 12 | H9: Trailing 3-Mo Avg × 12 | I9: Annualized Growth Rate | J9: Forecast Method
A10: Revenue | B10: € | C10: =AVERAGE('Income Statement'!B5:F5) -> 198380 | D10: =AVERAGE('Income Statement'!D5:F5) -> 203433.33 | E10: =IF('Income Statement'!B5<=0,0,('Income Statement'!F5/'Income Statement'!B5)^(1/$C$5)-1) -> 0.028997019 | F10: =IF(ABS(E10)>=$C$6,"Yes","No") -> Yes | G10: =C10*12 -> 2380560 | H10: =D10*12 -> 2441200 | I10: =(1+E10)^12-1 -> 0.4091895 | J10: =IF(F10="Yes","Monthly growth rate","5-month average") -> Monthly growth rate
B11: % of revenue | C11: =IF($C$10=0,0,C10/$C$10) -> 1 | D11: =IF($D$10=0,0,D10/$D$10) -> 1 | E11: =(1+E10)/(1+$E$10)-1 -> 0 | G11: =IF($G$10=0,0,G10/$G$10) -> 1 | H11: =IF($H$10=0,0,H10/$H$10) -> 1 | I11: =(1+I10)/(1+$I$10)-1 -> 0
A12: COGS (adjusted) | B12: € | C12: =AVERAGE('Income Statement'!B6:F6) -> 68680 | D12: =AVERAGE('Income Statement'!D6:F6) -> 72566.667 | E12: =IF('Income Statement'!B6<=0,0,('Income Statement'!F6/'Income Statement'!B6)^(1/$C$5)-1) -> 0.031562279 | F12: =IF(ABS(E12)>=$C$6,"Yes","No") -> Yes | G12: =C12*12 -> 824160 | H12: =D12*12 -> 870800 | I12: =(1+E12)^12-1 -> 0.45192919 | J12: =IF(F12="Yes","Monthly growth rate","5-month average") -> Monthly growth rate
B13: % of revenue | C13: =IF($C$10=0,0,C12/$C$10) -> 0.34620425 | D13: =IF($D$10=0,0,D12/$D$10) -> 0.35670981 | E13: =(1+E12)/(1+$E$10)-1 -> 0.002492972 | G13: =IF($G$10=0,0,G12/$G$10) -> 0.34620425 | H13: =IF($H$10=0,0,H12/$H$10) -> 0.35670981 | I13: =(1+I12)/(1+$I$10)-1 -> 0.030329275
A14: Payroll (adjusted) | B14: € | C14: =AVERAGE('Income Statement'!B11:F11) -> 72000 | D14: =AVERAGE('Income Statement'!D11:F11) -> 72000 | E14: =IF('Income Statement'!B11<=0,0,('Income Statement'!F11/'Income Statement'!B11)^(1/$C$5)-1) -> 0 | F14: =IF(ABS(E14)>=$C$6,"Yes","No") -> No | G14: =C14*12 -> 864000 | H14: =D14*12 -> 864000 | I14: =(1+E14)^12-1 -> 0 | J14: 5-month average (fixed cost)
B15: % of revenue | C15: =IF($C$10=0,0,C14/$C$10) -> 0.36293981 | D15: =IF($D$10=0,0,D14/$D$10) -> 0.3539243 | E15: =(1+E14)/(1+$E$10)-1 -> -0.028179886 | G15: =IF($G$10=0,0,G14/$G$10) -> 0.36293981 | H15: =IF($H$10=0,0,H14/$H$10) -> 0.3539243 | I15: =(1+I14)/(1+$I$10)-1 -> -0.29037223
A16: Consulting & Professional Fees (adjusted) | B16: € | C16: =AVERAGE('Income Statement'!B12:F12) -> 4100 | D16: =AVERAGE('Income Statement'!D12:F12) -> 4200 | E16: =IF('Income Statement'!B12<=0,0,('Income Statement'!F12/'Income Statement'!B12)^(1/$C$5)-1) -> -0.012424772 | F16: =IF(ABS(E16)>=$C$6,"Yes","No") -> No | G16: =C16*12 -> 49200 | H16: =D16*12 -> 50400 | I16: =(1+E16)^12-1 -> -0.13931893 | J16: 5-month average (fixed cost)
B17: % of revenue | C17: =IF($C$10=0,0,C16/$C$10) -> 0.020667406 | D17: =IF($D$10=0,0,D16/$D$10) -> 0.020645584 | E17: =(1+E16)/(1+$E$10)-1 -> -0.04025453 | G17: =IF($G$10=0,0,G16/$G$10) -> 0.020667406 | H17: =IF($H$10=0,0,H16/$H$10) -> 0.020645584 | I17: =(1+I16)/(1+$I$10)-1 -> -0.38923681
A18: Other OpEx | B18: € | C18: =AVERAGE('Income Statement'!B13:F13) -> 23140 | D18: =AVERAGE('Income Statement'!D13:F13) -> 23433.333 | E18: =IF('Income Statement'!B13<=0,0,('Income Statement'!F13/'Income Statement'!B13)^(1/$C$5)-1) -> 0.01640788 | F18: =IF(ABS(E18)>=$C$6,"Yes","No") -> No | G18: =C18*12 -> 277680 | H18: =D18*12 -> 281200 | I18: =(1+E18)^12-1 -> 0.21567163 | J18: 5-month average (fixed cost)
B19: % of revenue | C19: =IF($C$10=0,0,C18/$C$10) -> 0.11664482 | D19: =IF($D$10=0,0,D18/$D$10) -> 0.11518925 | E19: =(1+E18)/(1+$E$10)-1 -> -0.012234378 | G19: =IF($G$10=0,0,G18/$G$10) -> 0.11664482 | H19: =IF($H$10=0,0,H18/$H$10) -> 0.11518925 | I19: =(1+I18)/(1+$I$10)-1 -> -0.13732565
A22: Notes
A23: 1. On the % of revenue rows, the growth columns show how fast the line item grows relative to revenue: (1 + item growth) ÷ (1 + revenue growth) − 1. A positive figure means the cost is taking a rising share of revenue.
A24: 2. Annualized % of revenue equals the monthly figure, because annualizing scales the cost and revenue equally.
A25: 3. Month-over-month growth is noisy (for example, adjusted COGS rose 26% in Month 8 and fell 17% in Month 9), so the compound rate between endpoints is used.
A26: 4. Per instruction, OpEx lines are treated as fixed and forecast at their adjusted 5-month average regardless of growth.

Sheet Balance Sheet
A1: Balance Sheet — Months 6–10 Actual + Months 11–13 Forecast (linked to Income Statement)
A2: All figures in EUR (€). Opening cash and Month 9 closing cash come from the bookkeeper; other balances have not been provided (yellow cells).
A3: Legend: yellow fill / blue text = input · green = link to Income Statement · black = formula · purple-shaded italic columns = FORECAST
H4: FORECAST
A5: € | B5: Opening (End of Month 5) | C5: Month 6 | D5: Month 7 | E5: Month 8 | F5: Month 9 | G5: Month 10 | H5: Month 11 (F) | I5: Month 12 (F) | J5: Month 13 (F)
A6: ASSETS
A7: Cash | B7: =B32 -> 118000 | C7: =C56 -> 121700 | D7: =D56 -> 128400 | E7: =E56 -> 92000 | F7: =F56 -> 61000 | G7: =G56 -> 78000 | H7: =H56 -> 99365.008 | I7: =I56 -> 124742.65 | J7: =J56 -> 154243.48
A8: Accounts Receivable | H8: =G8 -> 0 | I8: =H8 -> 0 | J8: =I8 -> 0
A9: Other Current Assets (prepaids, WIP, etc.) | H9: =G9 -> 0 | I9: =H9 -> 0 | J9: =I9 -> 0
A10: Total Current Assets | B10: =SUM(B7:B9) -> 118000 | C10: =SUM(C7:C9) -> 121700 | D10: =SUM(D7:D9) -> 128400 | E10: =SUM(E7:E9) -> 92000 | F10: =SUM(F7:F9) -> 61000 | G10: =SUM(G7:G9) -> 78000 | H10: =SUM(H7:H9) -> 99365.008 | I10: =SUM(I7:I9) -> 124742.65 | J10: =SUM(J7:J9) -> 154243.48
A11: Fixed Assets (net) | H11: =G11 -> 0 | I11: =H11 -> 0 | J11: =I11 -> 0
A12: Reinvested in the Business (cumulative cash expenditures) | C12: =B12+C40 -> 24100 | D12: =C12+D40 -> 48200 | E12: =D12+E40 -> 72300 | F12: =E12+F40 -> 96400 | G12: =F12+G40 -> 120500 | H12: =G12+H40 -> 144600 | I12: =H12+I40 -> 168700 | J12: =I12+J40 -> 192800
A13: Other Non-Current Assets | H13: =G13 -> 0 | I13: =H13 -> 0 | J13: =I13 -> 0
A14: TOTAL ASSETS | B14: =B10+B11+B12+B13 -> 118000 | C14: =C10+C11+C12+C13 -> 145800 | D14: =D10+D11+D12+D13 -> 176600 | E14: =E10+E11+E12+E13 -> 164300 | F14: =F10+F11+F12+F13 -> 157400 | G14: =G10+G11+G12+G13 -> 198500 | H14: =H10+H11+H12+H13 -> 243965.01 | I14: =I10+I11+I12+I13 -> 293442.65 | J14: =J10+J11+J12+J13 -> 347043.48
A16: LIABILITIES
A17: Accounts Payable (incl. subcontractors) | H17: =G17 -> 0 | I17: =H17 -> 0 | J17: =I17 -> 0
A18: Accrued Payroll & Bonuses | H18: =G18 -> 0 | I18: =H18 -> 0 | J18: =I18 -> 0
A19: Accrued Expenses & Other Current Liabilities | H19: =G19 -> 0 | I19: =H19 -> 0 | J19: =I19 -> 0
A20: Total Current Liabilities | B20: =SUM(B17:B19) -> 0 | C20: =SUM(C17:C19) -> 0 | D20: =SUM(D17:D19) -> 0 | E20: =SUM(E17:E19) -> 0 | F20: =SUM(F17:F19) -> 0 | G20: =SUM(G17:G19) -> 0 | H20: =SUM(H17:H19) -> 0 | I20: =SUM(I17:I19) -> 0 | J20: =SUM(J17:J19) -> 0
A21: Long-Term Debt | H21: =G21 -> 0 | I21: =H21 -> 0 | J21: =I21 -> 0
A22: TOTAL LIABILITIES | B22: =B20+B21 -> 0 | C22: =C20+C21 -> 0 | D22: =D20+D21 -> 0 | E22: =E20+E21 -> 0 | F22: =F20+F21 -> 0 | G22: =G20+G21 -> 0 | H22: =H20+H21 -> 0 | I22: =I20+I21 -> 0 | J22: =J20+J21 -> 0
A24: EQUITY
A25: Share Capital | H25: =G25 -> 0 | I25: =H25 -> 0 | J25: =I25 -> 0
A26: Retained Earnings | B26: =B14-B22-B25 -> 118000 | C26: =C64 -> 145800 | D26: =D64 -> 176600 | E26: =E64 -> 164300 | F26: =F64 -> 157400 | G26: =G64 -> 198500 | H26: =H64 -> 243965.01 | I26: =I64 -> 293442.65 | J26: =J64 -> 347043.48
A27: TOTAL EQUITY | B27: =B25+B26 -> 118000 | C27: =C25+C26 -> 145800 | D27: =D25+D26 -> 176600 | E27: =E25+E26 -> 164300 | F27: =F25+F26 -> 157400 | G27: =G25+G26 -> 198500 | H27: =H25+H26 -> 243965.01 | I27: =I25+I26 -> 293442.65 | J27: =J25+J26 -> 347043.48
A28: TOTAL LIABILITIES & EQUITY | B28: =B22+B27 -> 118000 | C28: =C22+C27 -> 145800 | D28: =D22+D27 -> 176600 | E28: =E22+E27 -> 164300 | F28: =F22+F27 -> 157400 | G28: =G22+G27 -> 198500 | H28: =H22+H27 -> 243965.01 | I28: =I22+I27 -> 293442.65 | J28: =J22+J27 -> 347043.48
A29: Balance check: Assets − (Liabilities + Equity) → must be 0 | B29: =ROUND(B14-B28,2) -> 0 | C29: =ROUND(C14-C28,2) -> 0 | D29: =ROUND(D14-D28,2) -> 0 | E29: =ROUND(E14-E28,2) -> 0 | F29: =ROUND(F14-F28,2) -> 0 | G29: =ROUND(G14-G28,2) -> 0 | H29: =ROUND(H14-H28,2) -> 0 | I29: =ROUND(I14-I28,2) -> 0 | J29: =ROUND(J14-J28,2) -> 0
A31: CASH EXPENDITURES — WHY CASH FELL WHILE PROFITS WERE POSITIVE (Months 6–9)
A32: Cash balance at start of Month 6 (= end of Month 5) | B32: 118000
A33: Cash balance at start of Month 10 (= end of Month 9) | B33: 61000
A34: Net change in cash, Months 6–9 | B34: =B33-B32 -> -57000
A35: Cumulative reported net income, Months 6–9 | B35: =SUM(C45:F45) -> 39400
A36: Other identified cash movements, Months 6–9 (working capital, debt, equity, dividends) | B36: =SUM(C46:F54) -> 0
A37: Unexplained cash out → Cash Expenditures, Months 6–9 | B37: =B35+B36-B34 -> 96400
A38: Months smoothed over (Months 6, 7, 8, 9) | B38: 4
A39: Smoothed monthly cash expenditure | B39: =IF(B38=0,0,B37/B38) -> 24100
A40: Cash Expenditures (reinvestment, smoothed) | C40: =$B$39 -> 24100 | D40: =$B$39 -> 24100 | E40: =$B$39 -> 24100 | F40: =$B$39 -> 24100 | G40: =$B$39 -> 24100 | H40: =$B$39 -> 24100 | I40: =$B$39 -> 24100 | J40: =$B$39 -> 24100
A41: Check: derived end-of-Month-9 cash − €61,000 → must be 0 | B41: =ROUND(F7-B33,2) -> 0
A43: CASH BRIDGE — INDIRECT METHOD
A44: Opening Cash | C44: =B7 -> 118000 | D44: =C7 -> 121700 | E44: =D7 -> 128400 | F44: =E7 -> 92000 | G44: =F7 -> 61000 | H44: =G7 -> 78000 | I44: =H7 -> 99365.008 | J44: =I7 -> 124742.65
...
